Workbook

Sheet Instruction
A2: LOIN-Lighting Fixture | B2: This includes what LOIN embeds into and is expected to be delivered.
A3: IDS for LOIN | B3: This sheet contains the IDS prepared according to the LOIN. Picture is attached for comprehensive understanding of the input at sheet 3 (IDS for LOIN)
A5: The python script extracts information from sheet 3 and produces the IDS file
B7: It should be noted that the IDS can only provide the requirements based on its schema. Since the LOIN is rich in metadata, it may not be possible to include all the attributes of the properties. The best that could be done is to use : 1. Use URI element in IDS to link our property instance 2. Use Property description to instruct modeler "Refer the URI for property and see the property description to include all other attributes of the property" 3. For the Property Instruction, "For each property, add metadata: label, definition, identifier, unit, GUID"
A9: IDS official schema | B9: https://github.com/buildingSMART/IDS
A10: Free IDS viewer | B10: https://viewer.sortdesk.com/

Sheet LOIN-LightingFixture
A1: PREREQUISITES | F1: LOIN
A2: Milestone | B2: Purpose | C2: Actor | D2: Object_Name | E2: IFC entity | F2: PropertySet | G2: Property_BaseName | H2: Property_label | I2: Property_Definition | J2: Property_Unit | K2: Property_GUID | L2: Property_Identifier | M2: Data_Type | N2: Value_Enumerations
A3: DesignPhase | B3: LightingSimulation | C3: Lighting Product Manufacturer | D3: Lighting Fixture | E3: IfcFlowTerminal | F3: Pset_Electrical | G3: PowerFactor | H3: Power Factor | I3: Ratio of the amount of the active power to the apparant power at 100% load. See Also IEC 80000-6. | J3: UNITLESS | K3: 3LBrQkLDDFheBOxrGk8Zr_ | L3: 02-0003 | M3: FloatNumber
A4: DesignPhase | B4: LightingSimulation | C4: Lighting Product Manufacturer | D4: Lighting Fixture | E4: IfcFlowTerminal | F4: Pset_Electrical | G4: RatedVoltage | H4: Nominal mains volatage | I4: Nominal voltage at which the product operates normally as specified by the supplier or manufacturer. | J4: V | K4: 3ERn8VgnjDjhulH3MaG9yG | L4: 02-0028 | M4: FloatNumber
A5: DesignPhase | B5: LightingSimulation | C5: Lighting Product Manufacturer | D5: Lighting Fixture | E5: IfcFlowTerminal | F5: Pset_Electrical | G5: StandByPower | H5: Standby Power | I5: Power consumption of switched off luminaire. All electrical components including emergency and lighting controls components have to be considered. Is also known as parasitic power. See also EN 15193-1. | J5: W | K5: 0TzE4sMDv1pwfygK1xxjm5 | L5: 02-0006 | M5: FloatNumber
A6: DesignPhase | B6: LightingSimulation | C6: Lighting Product Manufacturer | D6: Lighting Fixture | E6: IfcFlowTerminal | F6: Pset_MechanicalAndInstallation | G6: MountingType | H6: Mounting Type | I6: Type of mounting used for the luminaire or sensing device. | J6: UNITLESS | K6: 3m5UX0NuH4YRPUJ1EmzXz7 | L6: 06-0003 | M6: String | N6: SurfaceMounted Pendant FreeStanding Recessed PartlyRecessed TrimlessRecessed PoleTop PoleSideEntry PoleIntegrated ConductorRail Connector Other
A7: DesignPhase | B7: LightingSimulation | C7: Lighting Product Manufacturer | D7: Lighting Fixture | E7: IfcFlowTerminal | F7: Pset_MechanicalAndInstallation | G7: Length | H7: Length | I7: Length of the housing of the luminaire or sensing device. Length is set parallel to the C90-C270 plane. Corresponds to y-axis and with 90 horizontal of the Light Distribution Curve. This definition is regardless of orientation of luminaires. See Figure 1. | J7: MilliM | K7: 1uJglYpRnFpQ4tStHaR2Pf | L7: 01-0003 | M7: FloatNumber
A8: DesignPhase | B8: LightingSimulation | C8: Lighting Product Manufacturer | D8: Lighting Fixture | E8: IfcFlowTerminal | F8: Pset_MechanicalAndInstallation | G8: IPRating | H8: Ingress protection IP Code | I8: The IP code classifies and rates the degree of protection provided against intrusion (body parts such as hands and fingers), dust, accidental contact, and water by mechanical casing and electrical enclosures. See Also, EN 60529. | J8: UNITLESS | K8: 1K_1K1q6n7KgOFJw5Cuc_i | L8: 02-0031 | M8: String | N8: IP20 IP21 IP22 IP23 IP24 IP25 IP26 IP27 IP28 IP30 IP31 IP32 IP33 IP34 IP35 IP36 IP37 IP38 IP40 IP41 IP42 IP43 IP44 IP45 IP46 IP47 IP48 IP50 IP51 IP52 IP53 IP54 IP55 IP56 IP57 IP58 IP60 IP61 IP62 IP63 IP64 IP65 IP66 IP67 IP68 IP69 IP69K
A9: DesignPhase | B9: LightingSimulation | C9: Lighting Product Manufacturer | D9: Lighting Fixture | E9: IfcFlowTerminal | F9: Pset_MechanicalAndInstallation | G9: Height | H9: Height | I9: Height of the housing of the luminaire or sensing device. Corresponds to z-axis, gaMilliM angle 180 and 180 vertical of the light distribution curve. This definition is regardless or orientation of luminaires. See Figures 1. | J9: MilliM | K9: 19Z9XKYDT4p8HR0ZbD$wO_ | L9: 01-0002 | M9: FloatNumber
A10: DesignPhase | B10: LightingSimulation | C10: Lighting Product Manufacturer | D10: Lighting Fixture | E10: IfcFlowTerminal | F10: Pset_MechanicalAndInstallation | G10: Width | H10: Width | I10: Width of the housing of the luminaire or sensing device. Width is set parallel to the C0-C180 plane. Corresponds to the x-axis and with 0 horizontal of the Light Distribution Curve. This definition is regardless of orientation of luminaires. See Figure 1. | J10: MilliM | K10: 1dPvrZN3vEIB0n0vwYvDcX | L10: 01-0004 | M10: FloatNumber
A11: DesignPhase | B11: LightingSimulation | C11: Lighting Product Manufacturer | D11: Lighting Fixture | E11: IfcFlowTerminal | F11: Pset_Photometric | G11: RatedLuminousFlux | H11: Rated Luminous flux of the light source | I11: Value of the initial luminous flux of a given type of light source declared by the manufacturer or the responsible vendor, the light source being operated at an ambient temperature of 25 degree celcius. See also EN13032-4. | J11: LM | K11: 2gmo70bVX90uJh2YAvS62s | L11: 04-0006 | M11: FloatNumber
A12: DesignPhase | B12: LightingSimulation | C12: Lighting Product Manufacturer | D12: Lighting Fixture | E12: IfcFlowTerminal | F12: Pset_Photometric | G12: LuminousEfficacy | H12: Luminous Efficacy | I12: Quotient of the luminous flux emitted by the luminaire and the power absorbed by the light source and associated circuits of the luminaire. | J12: LM-PER-W | K12: 1QmFILGbX6_BfU63rG5mrh | L12: 04-0007 | M12: FloatNumber
A13: DesignPhase | B13: LightingSimulation | C13: Lighting Product Manufacturer | D13: Lighting Fixture | E13: IfcFlowTerminal | F13: Pset_Photometric | G13: CorrelatedColorTemperature | H13: Correlated Color Temperature (CCT) | I13: The colour temperature of any source of radiation is defined as the temperature (in Kelvin) of a black-body or Planckian radiator whose radiation has the same chromaticity as the source radiation. See Also EN12665. | J13: K | K13: 0XeHsouWz8PxASJ4mpkdEY | L13: 04-0023 | M13: FloatNumber

Sheet IDS_FOR_LOIN
A1: <INFO> | C1: <SPECIFICATIONS> | G1: <SPECIFICATIONS>
A2: Info MetaData | C2: Specification | E2: Applicability | G2: Requirements
A3: Elements | B3: Values | C3: Element | D3: Values | E3: Element | F3: Values | G3: Requirement Type | H3: URI | I3: Cardinality | J3: Instructions | K3: PropertySet | L3: BaseName | M3: Value | N3: dataType | O3: Enumeration Value
A4: Title | B4: Lighting Fixture - LOIN Core Properties | C4: Name | D4: Lighting Fixture - LOIN Core Properties | E4: Applicability Type | F4: entity | G4: Property | I4: required | K4: Pset_Electrical | L4: PowerFactor | N4: IFCNORMALISEDRATIOMEASURE
A5: Copyright | C5: IfcVersion | D5: IFC2X3 | E5: Name | F5: IfcFlowTerminal | G5: Property | I5: required | K5: Pset_Electrical | L5: RatedVoltage | N5: IFCELECTRICVOLTAGEMEASURE
A6: Version | B6: 1.1 | C6: Identifier | E6: Predefined Type | G6: Property | I6: required | K6: Pset_Electrical | L6: StandByPower | N6: IFCPOWERMEASURE
A7: Description | B7: LOIN-aligned core electrical, photometric, and mechanical properties for IfcLightFixtureType. | C7: Description | D7: LOIN-aligned core electrical, photometric, and mechanical properties for IfcLightFixtureType. | G7: Property | I7: required | K7: Pset_MechanicalAndInstallation | L7: MountingType | M7: enumeration | N7: IFCLABEL | O7: SurfaceMounted Pendant FreeStanding Recessed PartlyRecessed TrimlessRecessed PoleTop PoleSideEntry PoleIntegrated ConductorRail Connector Other
A8: Author | B8: BIMEngineer@gmail.com | C8: Instruction | D8: The specification highlights the requirements from LOIN for Lighting Fixture based on SIS-CEN/TS 17623:2021. Follow URI to review properties through Data Dictionary. | G8: Property | I8: required | K8: Pset_MechanicalAndInstallation | L8: Length | N8: IFCLENGTHMEASURE
A9: Date | B9: 46003 | C9: Cardinality | D9: required | G9: Property | I9: required | K9: Pset_MechanicalAndInstallation | L9: IPRating | M9: enumeration | N9: IFCLABEL | O9: IP20 IP21 IP22 IP23 IP24 IP25 IP26 IP27 IP28 IP30 IP31 IP32 IP33 IP34 IP35 IP36 IP37 IP38 IP40 IP41 IP42 IP43 IP44 IP45 IP46 IP47 IP48 IP50 IP51 IP52 IP53 IP54 IP55 IP56 IP57 IP58 IP60 IP61 IP62 IP63 IP64 IP65 IP66 IP67 IP68 IP69 IP69K
A10: Purpose | B10: LightingSimulation | G10: Property | I10: required | K10: Pset_MechanicalAndInstallation | L10: Height | N10: IFCLENGTHMEASURE
A11: Milestone | B11: DesignPhase | G11: Property | I11: required | K11: Pset_MechanicalAndInstallation | L11: Width | N11: IFCLENGTHMEASURE
G12: Property | I12: required | K12: Pset_Photometric | L12: RatedLuminousFlux | N12: IFCLUMINOUSFLUXMEASURE
G13: Property | I13: required | K13: Pset_Photometric | L13: LuminousEfficacy | N13: IFCRATIOMEASURE
G14: Property | I14: required | K14: Pset_Photometric | L14: CorrelatedColorTemperature | N14: IFCTHERMODYNAMICTEMPERATUREMEASURE

Sheet Intrinsic & Extrinsic Property 
E4: Intrinsic Property Requirements
D5: Property Set | E5: Properties | F5: Property Requirements using Data Dictionary
F6: GUID | G6: ID | H6: Name | I6: Description | J6: Datatype | K6: Unit | L6: Value
D7: Pset_Photometric | E7: CorrelatedColorTemperature | F7: 0XeHsouWz8PxASJ4mpkdEY | G7: 04-0023 | H7: Correlated Color Temperature (CCT) | I7: The colour temperature of any source of radiation is defined as the temperature (in Kelvin) of a black-body or Planckian radiator whose radiation has the same chromaticity as the source radiation. See Also EN12665. | J7: float | K7: K
D8: Pset_Photometric | E8: RatedLuminousFlux | F8: 2gmo70bVX90uJh2YAvS62s | G8: 04-0006 | H8: Rated Luminous flux of the light source | I8: Value of the initial luminous flux of a given type of light source declared by the manufacturer or the responsible vendor, the light source being operated at an ambient temperature of 25 degree celcius. See also EN13032-4. | J8: float | K8: LM
D9: Pset_Photometric | E9: LuminousEfficacy | F9: 1QmFILGbX6_BfU63rG5mrh | G9: 04-0007 | H9: Luminous Efficacy | I9: Quotient of the luminous flux emitted by the luminaire and the power absorbed by the light source and associated circuits of the luminaire. | J9: float | K9: LM-Per-W
D10: Pset_Electrical | E10: SupplyVoltage | F10: 3ERn8VgnjDjhulH3MaG9yG | G10: 02-0028 | H10: Nominal mains volatage | I10: Nominal voltage at which the product operates normally as specified by the supplier or manufacturer. | J10: float | K10: V
D11: Pset_Electrical | E11: PowerFactor | F11: 3LBrQkLDDFheBOxrGk8Zr_ | G11: 02-0003 | H11: Power Factor | I11: Ratio of the amount of the active power to the apparant power at 100% load. See Also IEC 80000-6. | J11: float | K11: UNITLESS
D12: Pset_Electrical | E12: StandByPower | F12: 0TzE4sMDv1pwfygK1xxjm5 | G12: 02-0006 | H12: Standby Power | I12: Power consumption of switched off luminaire. All electrical components including emergency and lighting controls components have to be considered. Is also known as parasitic power. See also EN 15193-1. | J12: float | K12: W
D13: Pset_MechanicalAndInstallation | E13: Length | F13: 1uJglYpRnFpQ4tStHaR2Pf | G13: 01-0003 | H13: Length | I13: Length of the housing of the luminaire or sensing device. Length is set parallel to the C90-C270 plane. Corresponds to y-axis and with 90 horizontal of the Light Distribution Curve. This definition is regardless of orientation of luminaires. See Figure 1. | J13: float | K13: MilliM
D14: Pset_MechanicalAndInstallation | E14: Width | F14: 1dPvrZN3vEIB0n0vwYvDcX | G14: 01-0004 | H14: Width | I14: Width of the housing of the luminaire or sensing device. Width is set parallel to the C0-C180 plane. Corresponds to the x-axis and with 0 horizontal of the Light Distribution Curve. This definition is regardless of orientation of luminaires. See Figure 1. | J14: float | K14: MilliM
D15: Pset_MechanicalAndInstallation | E15: Height | F15: 19Z9XKYDT4p8HR0ZbD | G15: 01-0002 | H15: Height | I15: Height of the housing of the luminaire or sensing device. Corresponds to z-axis, gaMilliM angle 180 and 180 vertical of the light distribution curve. This definition is regardless or orientation of luminaires. See Figures 1. | J15: float | K15: MilliM
D16: Pset_MechanicalAndInstallation | E16: IPRating | F16: 1K_1K1q6n7KgOFJw5Cuc_i | G16: 02-0031 | H16: Ingress protection IP Code | I16: The IP code classifies and rates the degree of protection provided against intrusion (body parts such as hands and fingers), dust, accidental contact, and water by mechanical casing and electrical enclosures. See Also, EN 60529. | J16: string | K16: N/A | L16: IP20 IP21 IP22 IP23 IP24 IP25 IP26 IP27 IP28 IP30 IP31 IP32 IP33 IP34 IP35 IP36 IP37 IP38 IP40 IP41 IP42 IP43 IP44 IP45 IP46 IP47 IP48 IP50 IP51 IP52 IP53 IP54 IP55 IP56 IP57 IP58 IP60 IP61 IP62 IP63 IP64 IP65 IP66 IP67 IP68 IP69 IP69K
D17: Pset_MechanicalAndInstallation | E17: MountingType | F17: 3m5UX0NuH4YRPUJ1EmzXz7 | G17: 06-0003 | H17: Mounting Type | I17: Type of mounting used for the luminaire or sensing device. | J17: string | K17: N/A | L17: SurfaceMounted Pendant FreeStanding Recessed PartlyRecessed TrimlessRecessed PoleTop PoleSideEntry PoleIntegrated ConductorRail Connector Other
C23: Extrinsic Property Requirement
C24: Space | D24: Properties | E24: Requirements
C25: Office | D25: IP Rating | E25: 20 or above
D26: MountingType | E26: Pendent only if height>3
D27: MountingType | E27: Not allowed (FreeStanding PoleTop PoleSideEntry PoleIntegrated ConductorRail Connector Other)
D28: Correlated Color Temperature | E28: 3000-4000k
D32: Property Set | E32: Properties | F32: Intrinsic Property Requirements
F33: Presence | G33: DataType Requirement | H33: Value Requirement | I33: Enumeration Requirement
D34: PhotometricReq_PropertySet | E34: CorrelatedColorTemperature | F34: must exist | G34: float | H34: > 0 (CCT cannot be zero or negative) | I34: N/A
D35: PhotometricReq_PropertySet | E35: RatedLuminousFlux | F35: must exist | G35: float | H35: ≥ 0 (luminous flux cannot be negative) | I35: N/A
D36: PhotometricReq_PropertySet | E36: LuminousEfficacy | F36: must exist | G36: float | H36: > 0 (efficacy cannot be zero) | I36: N/A
D37: ElectricalReq_PropertySet | E37: RatedSupplyVoltage | F37: must exist | G37: float | H37: 220 ≤ Voltage ≤ 240 (230 +/- 10%) | I37: N/A
D38: ElectricalReq_PropertySet | E38: PowerFactor | F38: must exist | G38: float | H38: 0 ≤ PF ≤ 1 | I38: N/A
D39: ElectricalReq_PropertySet | E39: StandbyPower | F39: must exist | G39: float | H39: ≥ 0 (cannot be negative) | I39: N/A
D40: MechanicalInstallationReq_PropertySet | E40: Length | F40: must exist | G40: float | H40: > 0 (physical dimension cannot be negative) | I40: N/A
D41: MechanicalInstallationReq_PropertySet | E41: Width | F41: must exist | G41: float | H41: > 0 (dimension cannot be zero) | I41: N/A
D42: MechanicalInstallationReq_PropertySet | E42: Height | F42: must exist | G42: float | H42: > 0 (dimension cannot be zero) | I42: N/A
D43: MechanicalInstallationReq_PropertySet | E43: IPRating | F43: must exist | G43: string | H43: Must not be empty | I43: IP20 IP21 IP22 IP23 IP24 IP25 IP26 IP27 IP28 IP30 IP31 IP32 IP33 IP34 IP35 IP36 IP37 IP38 IP40 IP41 IP42 IP43 IP44 IP45 IP46 IP47 IP48 IP50 IP51 IP52 IP53 IP54 IP55 IP56 IP57 IP58 IP60 IP61 IP62 IP63 IP64 IP65 IP66 IP67 IP68 IP69 IP69K
D44: MechanicalInstallationReq_PropertySet | E44: MountingType | F44: must exist | G44: string | H44: Must not be empty | I44: SurfaceMounted Pendant FreeStanding Recessed PartlyRecessed TrimlessRecessed PoleTop PoleSideEntry PoleIntegrated ConductorRail Connector Other

Sheet Data
B1: Cardinality | C1: IFC Version | D1: Applicability Type | E1: Entity Facets
B2: required | C2: IFC2X3 | D2: entity | E2: IFC4X3_ADD2 | F2: IFC4 | G2: IFC2X3
B3: optional | C3: IFC4 | D3: partOf | E3: IfcActionRequest | F3: IfcActionRequest | G3: Ifc2DCompositeCurve
B4: prohibited | C4: IFC4X3_ADD2 | D4: classification | E4: IfcActor | F4: IfcActor | G4: IfcActionRequest
D5: attribute | E5: IfcActorRole | F5: IfcActorRole | G5: IfcActor
D6: property | E6: IfcActuator | F6: IfcActuator | G6: IfcActorRole
D7: material | E7: IfcActuatorType | F7: IfcActuatorType | G7: IfcActuatorType
E8: IfcAddress | F8: IfcAddress | G8: IfcAddress
E9: IfcAdvancedBrep | F9: IfcAdvancedBrep | G9: IfcAirTerminalBoxType
E10: IfcAdvancedBrepWithVoids | F10: IfcAdvancedBrepWithVoids | G10: IfcAirTerminalType
E11: IfcAdvancedFace | F11: IfcAdvancedFace | G11: IfcAirToAirHeatRecoveryType
E12: IfcAirTerminal | F12: IfcAirTerminal | G12: IfcAlarmType
E13: IfcAirTerminalBox | F13: IfcAirTerminalBox | G13: IfcAngularDimension
E14: IfcAirTerminalBoxType | F14: IfcAirTerminalBoxType | G14: IfcAnnotation
E15: IfcAirTerminalType | F15: IfcAirTerminalType | G15: IfcAnnotationCurveOccurrence
E16: IfcAirToAirHeatRecovery | F16: IfcAirToAirHeatRecovery | G16: IfcAnnotationFillArea
E17: IfcAirToAirHeatRecoveryType | F17: IfcAirToAirHeatRecoveryType | G17: IfcAnnotationFillAreaOccurrence
E18: IfcAlarm | F18: IfcAlarm | G18: IfcAnnotationOccurrence
E19: IfcAlarmType | F19: IfcAlarmType | G19: IfcAnnotationSurface
... E90: IfcCableFitting | F90: IfcChimney | G90: IfcColourSpecification
F91: IfcChimneyType | G91: IfcColumn
F92: IfcCircle | G92: IfcColumnType
F93: IfcCircleHollowProfileDef | G93: IfcComplexProperty
F94: IfcCircleProfileDef | G94: IfcCompositeCurve
F95: IfcCivilElement | G95: IfcCompositeCurveSegment
F96: IfcCivilElementType | G96: IfcCompositeProfileDef
F97: IfcClassification | G97: IfcCompressorType
F98: IfcClassificationReference | G98: IfcCondenserType
F99: IfcClosedShell | G99: IfcCondition
F100: IfcCoil | G100: IfcConditionCriterion
F101: IfcCoilType | G101: IfcConic
F102: IfcColourRgb | G102: IfcConnectedFaceSet
... F655: IfcStructuralMember | G655: IfcZone
F656: IfcStructuralPlanarAction
F657: IfcStructuralPointAction
F658: IfcStructuralPointConnection
F659: IfcStructuralPointReaction
F660: IfcStructuralReaction
F661: IfcStructuralResultGroup
F662: IfcStructuralSurfaceAction
...

Sheet DO NOT USE
A1: INFO | D1: SPECIFICATION | J1: APPLICABILITY | L1: REQUIREMENTS
A2: Milestone | B2: Purpose | C2: Author | D2: Specification_Name | E2: Specification_Identifier | F2: Specification_Description | G2: Specification_Instructions | H2: Specification_Cardinality | I2: IFC_Version | J2: IfcEntity | K2: IfcPredefinedType | L2: Requirement_Description | M2: PropertySet | N2: Property_Name | O2: Property_DataType | P2: Property_Cardinality | Q2: Property_URI | R2: Property_Instructions | S2: Value_Type | T2: Value_MinInclusive | U2: Value_MaxInclusive | V2: Value_Enumerations
A3: ='LOIN-LightingFixture'!A3 -> DesignPhase | B3: ='LOIN-LightingFixture'!B3 -> LightingSimulation | C3: BIMEngineer | D3: Lighting Fixture - LOIN Core Properties | F3: LOIN-aligned core electrical, photometric, and mechanical properties for IfcLightFixtureType. | G3: The specification highlights the requirements from LOIN for Lighting Fixture based on SIS-CEN/TS 17623:2021. See URI, instruction to include attributes to each property requirements. | H3: Required | I3: IFC4X3_ADD2 | J3: IfcLightFixtureType | L3: Ratio of the amount of the active power to the apparant power at 100% load. See Also IEC 80000-6." | M3: Pset_ElectricalAttributes | N3: Power Factor | O3: IFCNORMALISEDRATIOMEASURE | P3: Required | Q3: http://www.semanticweb.org/acer/ontologies/2025/3/LOINforLightingSimulation#CorrelatedColorTemperature | R3: In addition to the numeric values, provide metadata such as label, GUID, identifier, Units. See URI also.
A4: ='LOIN-LightingFixture'!A4 -> DesignPhase | B4: ='LOIN-LightingFixture'!B4 -> LightingSimulation | C4: BIMEngineer | D4: Lighting Fixture - LOIN Core Properties | F4: LOIN-aligned core electrical, photometric, and mechanical properties for IfcLightFixtureType. | G4: The specification highlights the requirements from LOIN for Lighting Fixture based on SIS-CEN/TS 17623:2021. See URI, instruction to include attributes to each property requirements. | H4: Required | I4: IFC4X3_ADD3 | J4: IfcLightFixtureType | L4: Nominal voltage at which the product operates normally as specified by the supplier or manufacturer. | M4: Pset_ElectricalAttributes | N4: Rated Voltage | O4: IFCELECTRICVOLTAGEMEASURE | P4: Required | Q4: http://www.semanticweb.org/acer/ontologies/2025/3/LOINforLightingSimulation#LumenOutput | R4: In addition to the numeric values, provide metadata such as label, GUID, identifier, Units. See URI also.
A5: ='LOIN-LightingFixture'!A5 -> DesignPhase | B5: ='LOIN-LightingFixture'!B5 -> LightingSimulation | C5: BIMEngineer | D5: Lighting Fixture - LOIN Core Properties | F5: LOIN-aligned core electrical, photometric, and mechanical properties for IfcLightFixtureType. | G5: The specification highlights the requirements from LOIN for Lighting Fixture based on SIS-CEN/TS 17623:2021. See URI, instruction to include attributes to each property requirements. | H5: Required | I5: IFC4X3_ADD4 | J5: IfcLightFixtureType | L5: Power consumption of switched off luminaire. All electrical components including emergency and lighting controls components have to be considered. Is also known as parasitic power. See also EN 15193-1. | M5: Pset_ElectricalAttributes | N5: Standby Power | O5: IFCELECTRICPOWERMEASURE | P5: Required | Q5: http://www.semanticweb.org/acer/ontologies/2025/3/LOINforLightingSimulation#LuminousEfficacy | R5: In addition to the numeric values, provide metadata such as label, GUID, identifier, Units. See URI also.
A6: ='LOIN-LightingFixture'!A6 -> DesignPhase | B6: ='LOIN-LightingFixture'!B6 -> LightingSimulation | C6: BIMEngineer | D6: Lighting Fixture - LOIN Core Properties | F6: LOIN-aligned core electrical, photometric, and mechanical properties for IfcLightFixtureType. | G6: The specification highlights the requirements from LOIN for Lighting Fixture based on SIS-CEN/TS 17623:2021. See URI, instruction to include attributes to each property requirements. | H6: Required | I6: IFC4X3_ADD5 | J6: IfcLightFixtureType | L6: Type of mounting used for the luminaire or sensing device. | M6: Pset_Mechanical&InstallationAttributes | N6: Mounting Type | O6: IFCIDENTIFIER | P6: Required | Q6: http://www.semanticweb.org/acer/ontologies/2025/3/LOINforLightingSimulation#RatedVoltage | R6: In addition to the numeric values, provide metadata such as label, GUID, identifier, Units. See URI also. | S6: enumeration | V6: SurfaceMounted Pendant FreeStanding Recessed PartlyRecessed TrimlessRecessed PoleTop PoleSideEntry PoleIntegrated ConductorRail Connector Other
A7: ='LOIN-LightingFixture'!A7 -> DesignPhase | B7: ='LOIN-LightingFixture'!B7 -> LightingSimulation | C7: BIMEngineer | D7: Lighting Fixture - LOIN Core Properties | F7: LOIN-aligned core electrical, photometric, and mechanical properties for IfcLightFixtureType. | G7: The specification highlights the requirements from LOIN for Lighting Fixture based on SIS-CEN/TS 17623:2021. See URI, instruction to include attributes to each property requirements. | H7: Required | I7: IFC4X3_ADD6 | J7: IfcLightFixtureType | L7: Length of the housing of the luminaire or sensing device. Length is set parallel to the C90-C270 plane. Corresponds to y-axis and with 90 horizontal of the Light Distribution Curve. This definition is regardless of orientation of luminaires. See Figure 1. | M7: Pset_Mechanical&InstallationAttributes | N7: Length | O7: IFCLENGTHMEASURE | P7: Required | Q7: http://www.semanticweb.org/acer/ontologies/2025/3/LOINforLightingSimulation#PowerFactor | R7: In addition to the numeric values, provide metadata such as label, GUID, identifier, Units. See URI also.
A8: ='LOIN-LightingFixture'!A8 -> DesignPhase | B8: ='LOIN-LightingFixture'!B8 -> LightingSimulation | C8: BIMEngineer | D8: Lighting Fixture - LOIN Core Properties | F8: LOIN-aligned core electrical, photometric, and mechanical properties for IfcLightFixtureType. | G8: The specification highlights the requirements from LOIN for Lighting Fixture based on SIS-CEN/TS 17623:2021. See URI, instruction to include attributes to each property requirements. | H8: Required | I8: IFC4X3_ADD7 | J8: IfcLightFixtureType | L8: The IP code classifies and rates the degree of protection provided against intrusion (body parts such as hands and fingers), dust, accidental contact, and water by mechanical casing and electrical enclosures. See Also, EN 60529. | M8: Pset_Mechanical&InstallationAttributes | N8: IP Rating | O8: IFCIDENTIFIER | P8: Required | Q8: http://www.semanticweb.org/acer/ontologies/2025/3/LOINforLightingSimulation#StandByPower | R8: In addition to the numeric values, provide metadata such as label, GUID, identifier, Units. See URI also. | S8: enumeration | V8: IP20 IP21 IP22 IP23 IP24 IP25 IP26 IP27 IP28 IP30 IP31 IP32 IP33 IP34 IP35 IP36 IP37 IP38 IP40 IP41 IP42 IP43 IP44 IP45 IP46 IP47 IP48 IP50 IP51 IP52 IP53 IP54 IP55 IP56 IP57 IP58 IP60 IP61 IP62 IP63 IP64 IP65 IP66 IP67 IP68 IP69 IP69K
A9: ='LOIN-LightingFixture'!A9 -> DesignPhase | B9: ='LOIN-LightingFixture'!B9 -> LightingSimulation | C9: BIMEngineer | D9: Lighting Fixture - LOIN Core Properties | F9: LOIN-aligned core electrical, photometric, and mechanical properties for IfcLightFixtureType. | G9: The specification highlights the requirements from LOIN for Lighting Fixture based on SIS-CEN/TS 17623:2021. See URI, instruction to include attributes to each property requirements. | H9: Required | I9: IFC4X3_ADD8 | J9: IfcLightFixtureType | L9: Height of the housing of the luminaire or sensing device. Corresponds to z-axis, gaMilliM angle 180 and 180 vertical of the light distribution curve. This definition is regardless or orientation of luminaires. See Figures 1. | M9: Pset_Mechanical&InstallationAttributes | N9: Height | O9: IFCLENGTHMEASURE | P9: Required | Q9: http://www.semanticweb.org/acer/ontologies/2025/3/LOINforLightingSimulation#Length | R9: In addition to the numeric values, provide metadata such as label, GUID, identifier, Units. See URI also.
A10: ='LOIN-LightingFixture'!A10 -> DesignPhase | B10: ='LOIN-LightingFixture'!B10 -> LightingSimulation | C10: BIMEngineer | D10: Lighting Fixture - LOIN Core Properties | F10: LOIN-aligned core electrical, photometric, and mechanical properties for IfcLightFixtureType. | G10: The specification highlights the requirements from LOIN for Lighting Fixture based on SIS-CEN/TS 17623:2021. See URI, instruction to include attributes to each property requirements. | H10: Required | I10: IFC4X3_ADD9 | J10: IfcLightFixtureType | L10: Width of the housing of the luminaire or sensing device. Width is set parallel to the C0-C180 plane. Corresponds to the x-axis and with 0 horizontal of the Light Distribution Curve. This definition is regardless of orientation of luminaires. See Figure 1. | M10: Pset_Mechanical&InstallationAttributes | N10: Width | O10: IFCLENGTHMEASURE | P10: Required | Q10: http://www.semanticweb.org/acer/ontologies/2025/3/LOINforLightingSimulation#Width | R10: In addition to the numeric values, provide metadata such as label, GUID, identifier, Units. See URI also.
A11: ='LOIN-LightingFixture'!A11 -> DesignPhase | B11: ='LOIN-LightingFixture'!B11 -> LightingSimulation | C11: BIMEngineer | D11: Lighting Fixture - LOIN Core Properties | F11: LOIN-aligned core electrical, photometric, and mechanical properties for IfcLightFixtureType. | G11: The specification highlights the requirements from LOIN for Lighting Fixture based on SIS-CEN/TS 17623:2021. See URI, instruction to include attributes to each property requirements. | H11: Required | I11: IFC4X3_ADD10 | J11: IfcLightFixtureType | L11: Value of the initial luminous flux of a given type of light source declared by the manufacturer or the responsible vendor, the light source being operated at an ambient temperature of 25 degree celcius. See also EN13032-4. | M11: Pset_PhotometricAttributes | N11: Rated Luminous Flux | O11: IFCLUMINOUSFLUXMEASURE | P11: Required | Q11: http://www.semanticweb.org/acer/ontologies/2025/3/LOINforLightingSimulation#Height | R11: In addition to the numeric values, provide metadata such as label, GUID, identifier, Units. See URI also.
A12: ='LOIN-LightingFixture'!A12 -> DesignPhase | B12: ='LOIN-LightingFixture'!B12 -> LightingSimulation | C12: BIMEngineer | D12: Lighting Fixture - LOIN Core Properties | F12: LOIN-aligned core electrical, photometric, and mechanical properties for IfcLightFixtureType. | G12: The specification highlights the requirements from LOIN for Lighting Fixture based on SIS-CEN/TS 17623:2021. See URI, instruction to include attributes to each property requirements. | H12: Required | I12: IFC4X3_ADD11 | J12: IfcLightFixtureType | L12: Quotient of the luminous flux emitted by the luminaire and the power absorbed by the light source and associated circuits of the luminaire. | M12: Pset_PhotometricAttributes | N12: Luminous Efficacy | O12: IFCRATIOMEASURE | P12: Required | Q12: http://www.semanticweb.org/acer/ontologies/2025/3/LOINforLightingSimulation#IPRating | R12: In addition to the numeric values, provide metadata such as label, GUID, identifier, Units. See URI also.
A13: ='LOIN-LightingFixture'!A13 -> DesignPhase | B13: ='LOIN-LightingFixture'!B13 -> LightingSimulation | C13: BIMEngineer | D13: Lighting Fixture - LOIN Core Properties | F13: LOIN-aligned core electrical, photometric, and mechanical properties for IfcLightFixtureType. | G13: The specification highlights the requirements from LOIN for Lighting Fixture based on SIS-CEN/TS 17623:2021. See URI, instruction to include attributes to each property requirements. | H13: Required | I13: IFC4X3_ADD12 | J13: IfcLightFixtureType | L13: The colour temperature of any source of radiation is defined as the temperature (in Kelvin) of a black-body or Planckian radiator whose radiation has the same chromaticity as the source radiation. See Also EN12665. | M13: Pset_PhotometricAttributes | N13: Correlated Color Temperature | O13: IFCTHERMODYNAMICTEMPERATUREMEASURE | P13: Required | Q13: http://www.semanticweb.org/acer/ontologies/2025/3/LOINforLightingSimulation#MountingType | R13: In addition to the numeric values, provide metadata such as label, GUID, identifier, Units. See URI also.
